Workbook

Sheet （单动-高速压机OP20）
A1: PFS 冲压件工艺卡 | AS1: 版本 | AZ1: 1.1
AS2: 生产线 | AZ2: MEB-100/200 | BI2: MEB-100/200 | BJ2: OP20 | BK2: 舒勒 | BL2: 宝钢（BAOSTEEL） | BM2: DC04 | BN2: 是 | BO2: CBF0（左、右） | BP2: （± 50KN） | BQ2: （KN） | BR2: 100 | BS2: 硬支撑 | BT2: ● | BU2: （是） | BV2: 8 | BW2: KN
A3: 零件号 | I3: 11A 809 605 | P3: 零件名称 | W3: 左侧围外板 | AD3: 适用车型 | AL3: A SUVe | AS3: 工序号 | AZ3: OP20 | BI3: 7-200 | BJ3: OP30 | BK3: 济二 | BL3: 大连蒂森（TAGAL） | BM3: DC04+ZE50/50BPO | BN3: 否 | BO3: CBF1（左、右） | BP3: （± 0.2Mpa） | BQ3: （Bar） | BR3: 0.5 | BS3: / | BT3: ○ | BU3: （否） | BV3: 9 | BW3: Bar
A4: 本工序用料情况 | AD4: 料片架堆料定位图 | BE4: ↑ | BI4: 6-100 | BJ4: OP40 | BL4: 浦项（POSCO） | BM4: DC04-A-m | BN4: / | BO4: CBF2（左、右） | BQ4: （Mpa） | BR4: 0.05 | BT4: ◎ | BV4: 10
A5: 原材料规格 | I5: 0.70*落料片 | AA5: mm | BI5: 6-200 | BJ5: OP50 | BL5: 广东浦项（POSCO Guangdong） | BM5: DC05+ZE50/50BPO | BO5: CBF3（左、右） | BT5: × | BV5: 11
A6: 材料牌号 | I6: CR5-EG29/29-EPO | BE6: 送 料方向 | BI6: 6-300 | BJ6: OP60 | BL6: 广州JFE（GJSS） | BM6: DC05-A-m | BO6: CBF4（左、右） | BT6: ☆ | BV6: 12
A7: 已认可供货商 | I7: 宝钢（BAOSTEEL） | BI7: 5-100 | BJ7: OP70 | BL7: 武钢（WISCO） | BM7: DC05+ZE75/75BP0 | BO7: CBF5（左、右） | BV7: 13
BI8: 5-200 | BL8: 鞍钢（ANSTEEL） | BM8: DC06+ZE50/50BPO | BO8: CBF6（左、右） | BV8: 14
A9: 本工序模具参数 | BI9: 4-100 | BL9: 阿赛洛（ARCELOR） | BM9: DX53D+Z100MB | BV9: 15
A10: 模具编号 | I10: 78-72D-058001 | AD10: 压机 形式 | AS10: 舒勒 | BI10: 3-600 | BL10: 蒂森（TKS） | BM10: DX53D+Z100MC | BV10: 16
A11: 模具名称 | I11: 拉延模 | AD11: 上模夹紧形式及数量 | AS11: 12 | BD11: 自动 | BL11: 瑞钢（SSAB） | BM11: DX54D+Z100MB | BV11: 17
A12: 模具总重量 | I12: 44.5 | AB12: T | AD12: 下模夹紧形式及数量 | AS12: 4 | BD12: 手动 | BL12: 首钢（Shougang） | BM12: DX54D+Z100MC
A13: 上模重量 | I13: 17.5 | AB13: T | AD13: 撑头形式及数量 | AS13: / | BD13: / | BL13: 宝钢阿赛洛（Shanghai Baosteel & Arcelor Tailor Metal） | BM13: DX56D+Z100MB
A14: 闭合高度 | I14: 1374 | S14: ±2 | AB14: mm | AD14: 使用压机吨位 | AF14: / | AS14: 2100 | BD14: T | BL14: 无 | BM14: DX56D+Z100MB+NIT
A15: 装模高度 | I15: 1430 | S15: ±2 | AB15: mm | AD15: 压机平衡缸压力 | AS15: / | BD15: Bar | BM15: DX56D+Z100MC
G16: -14 | H16: -13 | I16: -12 | J16: -11 | K16: -10 | L16: -9 | M16: -8 | N16: -7 | O16: -6 | P16: -5 | Q16: -4 | R16: -3 | S16: -2 | T16: -1 | U16: 0 | V16: 1 | W16: 2 | X16: 3 | Y16: 4 | Z16: 5 | AA16: 6 | AB16: 7 | AC16: 8 | AD16: 9 | AE16: 10 | AF16: 11 | AG16: 12 | AH16: 13 | AI16: 14 | AU16: 图例 | AX16: ◎ | AY16: 定位销 | BC16: ● | BD16: 顶棒 | BM16: DX56D+Z100NC
AX17: ○ | AY17: 顶棒/定位销孔 | BM17: DX57D+Z100MB
B18: 定位销及气垫顶棒分布图 | F18: 6 | G18: × | H18: × | I18: × | J18: ◎ | K18: ○ | L18: ○ | M18: ○ | N18: ○ | O18: ○ | P18: ○ | Q18: ○ | R18: ● | S18: ○ | T18: ○ | U18: ○ | V18: ● | W18: ○ | X18: ● | Y18: ○ | Z18: ○ | AA18: ○ | AB18: ● | AC18: ○ | AD18: ○ | AE18: ○ | AF18: ◎ | AG18: × | AH18: × | AI18: × | AJ18: 6 | AY18: 全顶棒图变化点 | BM18: DX57D+Z100MC
F19: 5 | G19: × | H19: × | I19: ○ | J19: ○ | K19: ○ | L19: ○ | M19: ● | N19: ○ | O19: ● | P19: ○ | Q19: ● | R19: ○ | S19: ● | T19: ○ | U19: ● | V19: ○ | W19: ● | X19: ○ | Y19: ● | Z19: ○ | AA19: ● | AB19: ○ | AC19: ● | AD19: ● | AE19: ● | AF19: ○ | AG19: ○ | AH19: × | AI19: × | AJ19: 5 | AX19: × | AY19: 禁止放顶棒 | BM19: H180BD+Z100MC
F20: 4 | G20: × | H20: ○ | I20: ○ | J20: ○ | K20: ● | L20: ● | M20: ○ | N20: ● | O20: ● | P20: ○ | Q20: ○ | R20: ○ | S20: ○ | T20: ○ | U20: ○ | V20: ○ | W20: ○ | X20: ○ | Y20: ○ | Z20: ○ | AA20: ○ | AB20: ○ | AC20: ○ | AD20: ○ | AE20: ○ | AF20: ● | AG20: ● | AH20: ○ | AI20: × | AJ20: 4 | BM20: H180YD+Z100MB
F21: 3 | G21: × | H21: ○ | I21: ○ | J21: ● | K21: ○ | L21: ○ | M21: ○ | N21: ○ | O21: ○ | P21: ○ | Q21: ○ | R21: ○ | S21: ○ | T21: ○ | U21: ○ | V21: ○ | W21: ○ | X21: ○ | Y21: ○ | Z21: ○ | AA21: ○ | AB21: ○ | AC21: ○ | AD21: ○ | AE21: ○ | AF21: ○ | AG21: ○ | AH21: ○ | AI21: × | AJ21: 3 | AT21: 是否使用闭锁 | BA21: 否 | BM21: H220BD+Z100MC
F22: 2 | G22: × | H22: ○ | I22: ○ | J22: ● | K22: ○ | L22: ○ | M22: ○ | N22: ○ | O22: ○ | P22: ○ | Q22: ○ | R22: ○ | S22: ○ | T22: ● | U22: ● | V22: ● | W22: ○ | X22: ○ | Y22: ● | Z22: ● | AA22: ● | AB22: ● | AC22: ● | AD22: ○ | AE22: ○ | AF22: ● | AG22: ○ | AH22: ○ | AI22: × | AJ22: 2 | AT22: 拉伸垫缸压力 （±50KN） | AZ22: 1 | BA22: 400 | BM22: H220BD+ZE50/50BPO
F23: 1 | G23: × | H23: ○ | I23: ● | J23: ○ | K23: ○ | L23: ○ | M23: ○ | N23: ○ | O23: ○ | P23: ○ | Q23: ○ | R23: ○ | S23: ● | T23: ○ | U23: ○ | V23: ● | W23: ○ | X23: ○ | Y23: ● | Z23: ○ | AA23: ○ | AB23: ○ | AC23: ● | AD23: ○ | AE23: ○ | AF23: ○ | AG23: ● | AH23: ○ | AI23: × | AJ23: 1 | AZ23: 2 | BA23: 400 | BM23: H220P
F24: 0 | G24: × | H24: ○ | I24: ○ | J24: ● | K24: ○ | L24: ○ | M24: ○ | N24: ○ | O24: ○ | P24: ○ | Q24: ○ | R24: ○ | S24: ● | T24: ○ | U24: ● | V24: ● | W24: ○ | X24: ○ | Y24: ● | Z24: ○ | AA24: ○ | AB24: ○ | AC24: ● | AD24: ○ | AE24: ○ | AF24: ○ | AG24: ○ | AH24: ○ | AI24: × | AJ24: 0 | AZ24: 3 | BA24: 400 | BM24: H220YD+Z100MB
F25: -1 | G25: × | H25: ○ | I25: ● | J25: ○ | K25: ○ | L25: ○ | M25: ○ | N25: ○ | O25: ○ | P25: ○ | Q25: ○ | R25: ● | S25: ○ | T25: ○ | U25: ● | V25: ○ | W25: ○ | X25: ○ | Y25: ● | Z25: ○ | AA25: ○ | AB25: ○ | AC25: ● | AD25: ○ | AE25: ○ | AF25: ○ | AG25: ● | AH25: ○ | AI25: × | AJ25: -1 | AZ25: 4 | BA25: 400 | BM25: H260LA
F26: -2 | G26: × | H26: ○ | I26: ○ | J26: ● | K26: ○ | L26: ○ | M26: ○ | N26: ○ | O26: ○ | P26: ○ | Q26: ● | R26: ● | S26: ○ | T26: ○ | U26: ● | V26: ○ | W26: ○ | X26: ● | Y26: ● | Z26: ● | AA26: ● | AB26: ● | AC26: ○ | AD26: ○ | AE26: ○ | AF26: ● | AG26: ● | AH26: ○ | AI26: × | AJ26: -2 | AZ26: 5 | BA26: 400 | BM26: H260LAD+Z100MB
F27: -3 | G27: × | H27: ○ | I27: ○ | J27: ● | K27: ● | L27: ○ | M27: ○ | N27: ○ | O27: ○ | P27: ○ | Q27: ○ | R27: ● | S27: ● | T27: ● | U27: ● | V27: ○ | W27: ○ | X27: ● | Y27: ● | Z27: ○ | AA27: ○ | AB27: ○ | AC27: ○ | AD27: ● | AE27: ● | AF27: ○ | AG27: ○ | AH27: ○ | AI27: × | AJ27: -3 | AZ27: 6 | BA27: 400 | BM27: H260LAD+Z140MB
F28: -4 | G28: × | H28: ○ | I28: ○ | J28: ○ | K28: ○ | L28: ● | M28: ● | N28: ○ | O28: ○ | P28: ○ | Q28: ○ | R28: ○ | S28: ○ | T28: ○ | U28: ○ | V28: ○ | W28: ○ | X28: ○ | Y28: ○ | Z28: ○ | AA28: ○ | AB28: ● | AC28: ○ | AD28: ○ | AE28: ○ | AF28: ○ | AG28: ○ | AH28: ○ | AI28: × | AJ28: -4 | AZ28: 7 | BA28: 400 | BM28: H260PD+Z100MB
F29: -5 | G29: × | H29: × | I29: ○ | J29: ○ | K29: ○ | L29: ○ | M29: ○ | N29: ● | O29: ● | P29: ○ | Q29: ● | R29: ○ | S29: ● | T29: ○ | U29: ● | V29: ○ | W29: ● | X29: ○ | Y29: ● | Z29: ○ | AA29: ● | AB29: ○ | AC29: ○ | AD29: ○ | AE29: ○ | AF29: ○ | AG29: ○ | AH29: × | AI29: × | AJ29: -5 | AZ29: 8 | BA29: 400 | BM29: H340LA
F30: -6 | G30: × | H30: × | I30: × | J30: ◎ | K30: ○ | L30: ○ | M30: ○ | N30: ● | O30: ○ | P30: ○ | Q30: ○ | R30: ● | S30: ○ | T30: ○ | U30: ○ | V30: ● | W30: ○ | X30: ● | Y30: ○ | Z30: ○ | AA30: ○ | AB30: ● | AC30: ○ | AD30: ○ | AE30: ○ | AF30: ◎ | AG30: × | AH30: × | AI30: × | AJ30: -6 | AT30: 拉伸垫顶棒数量 | BA30: 87 | BM30: H340LAD+Z100MB
AT31: 上死点高度 （±2mm） | BA31: 200 | BM31: HC180B+ZE50/50BPO
G32: -14 | H32: -13 | I32: -12 | J32: -11 | K32: -10 | L32: -9 | M32: -8 | N32: -7 | O32: -6 | P32: -5 | Q32: -4 | R32: -3 | S32: -2 | T32: -1 | U32: 0 | V32: 1 | W32: 2 | X32: 3 | Y32: 4 | Z32: 5 | AA32: 6 | AB32: 7 | AC32: 8 | AD32: 9 | AE32: 10 | AF32: 11 | AG32: 12 | AH32: 13 | AI32: 14 | BM32: HC220B+ZE50/50BPO
H33: -13 | I33: -12 | J33: -11 | K33: -10 | L33: -9 | M33: -8 | N33: -7 | O33: -6 | P33: -5 | Q33: -4 | R33: -3 | S33: -2 | T33: -1 | U33: 0 | V33: 1 | W33: 2 | X33: 3 | Y33: 4 | Z33: 5 | AA33: 6 | AB33: 7 | AC33: 8 | AD33: 9 | AE33: 10 | AF33: 11 | AG33: 12 | AH33: 13 | AV33: 图例 | BA33: ● | BB33: 顶棒 | BM33: HC220I+ZE50/50BPO
BA34: ○ | BB34: 顶棒孔 | BM34: HC220YD+Z100MC
F35: 6 | H35: ○ | I35: ○ | J35: ○ | K35: ○ | L35: ○ | M35: ○ | N35: ○ | O35: ○ | P35: ○ | Q35: ○ | R35: ○ | S35: ○ | T35: ○ | U35: ○ | V35: ○ | W35: ○ | X35: ○ | Y35: ○ | Z35: ○ | AA35: ○ | AB35: ○ | AC35: ○ | AD35: ○ | AE35: ○ | AF35: ○ | AG35: ○ | AH35: ○ | AJ35: 6 | BM35: HC300LA
B36: 滑块气垫顶棒分布图 | F36: 5 | H36: ○ | I36: ○ | J36: ○ | K36: ○ | L36: ○ | M36: ○ | N36: ○ | O36: ○ | P36: ○ | Q36: ○ | R36: ○ | S36: ○ | T36: ○ | U36: ○ | V36: ○ | W36: ○ | X36: ○ | Y36: ○ | Z36: ○ | AA36: ○ | AB36: ○ | AC36: ○ | AD36: ○ | AE36: ○ | AF36: ○ | AG36: ○ | AH36: ○ | AJ36: 5 | BM36: HC340LAD+Z100MB
F37: 4 | H37: ○ | I37: ○ | J37: ○ | K37: ○ | L37: ○ | M37: ○ | N37: ○ | O37: ○ | P37: ○ | Q37: ○ | R37: ○ | S37: ○ | T37: ○ | U37: ○ | V37: ○ | W37: ○ | X37: ○ | Y37: ○ | Z37: ○ | AA37: ○ | AB37: ○ | AC37: ○ | AD37: ○ | AE37: ○ | AF37: ○ | AG37: ○ | AH37: ○ | AJ37: 4 | BM37: HC420LA
F38: 3 | H38: ○ | I38: ○ | J38: ○ | K38: ○ | L38: ○ | M38: ○ | N38: ○ | O38: ○ | P38: ○ | Q38: ○ | R38: ○ | S38: ○ | T38: ○ | U38: ○ | V38: ○ | W38: ○ | X38: ○ | Y38: ○ | Z38: ○ | AA38: ○ | AB38: ○ | AC38: ○ | AD38: ○ | AE38: ○ | AF38: ○ | AG38: ○ | AH38: ○ | AJ38: 3 | BM38: HC450XD+Z100MB
F39: 2 | H39: ○ | I39: ○ | J39: ○ | K39: ○ | L39: ○ | M39: ○ | N39: ○ | O39: ○ | P39: ○ | Q39: ○ | R39: ○ | S39: ○ | T39: ○ | U39: ○ | V39: ○ | W39: ○ | X39: ○ | Y39: ○ | Z39: ○ | AA39: ○ | AB39: ○ | AC39: ○ | AD39: ○ | AE39: ○ | AF39: ○ | AG39: ○ | AH39: ○ | AJ39: 2 | BM39: HX180BD+Z100MB
F40: 1 | H40: ○ | I40: ○ | J40: ○ | K40: ○ | L40: ○ | M40: ○ | N40: ○ | O40: ○ | P40: ○ | Q40: ○ | R40: ○ | S40: ○ | T40: ○ | U40: ○ | V40: ○ | W40: ○ | X40: ○ | Y40: ○ | Z40: ○ | AA40: ○ | AB40: ○ | AC40: ○ | AD40: ○ | AE40: ○ | AF40: ○ | AG40: ○ | AH40: ○ | AJ40: 1 | BM40: HX180BD+Z100MC
...

Sheet 单动-高速压机OP30
A1: PFS 冲压件工艺卡 | AS1: 版本 | AZ1: 1.11
AS2: 生产线 | AZ2: MEB-100/200 | BH2: MEB-100/200 | BI2: ● | BJ2: 舒勒 | BK2: OP20 | BL2: CBF0（左、右） | BM2: （± 50KN） | BN2: 切边模 | BO2: 专用料架 | BP2: KN | BQ2: 4-100 | BR2: ○ | BS2: ◎
A3: 零件号 | I3: ='（单动-高速压机OP20）'!I3:O3 -> 11A 809 605 | P3: 零件名称 | W3: ='（单动-高速压机OP20）'!W3:AC3 -> 左侧围外板 | AD3: 适用车型 | AL3: ='（单动-高速压机OP20）'!AL3:AR3 -> A SUVe | AS3: 工序号 | AZ3: OP30 | BH3: 7-200 | BI3: ○ | BJ3: 济二 | BK3: OP30 | BL3: CBF1（左、右） | BM3: （± 0.2Mpa） | BN3: 翻边模 | BO3: 7V1通用料箱 | BP3: Bar | BQ3: 5-100 | BR3: ○ | BS3: ◎
A4: 本工序模具参数 | BH4: 6-100 | BI4: ◎ | BK4: OP40 | BL4: CBF2（左、右） | BN4: 整形模 | BO4: 7V2通用料箱 | BQ4: 5-200 | BR4: ○ | BS4: ◎
A5: 模具编号 | I5: 78-72D-058003 | AD5: 压机 形式 | AS5: 舒勒 | BH5: 6-200 | BK5: OP50 | BL5: CBF3（左、右） | BN5: 冲孔模 | BO5: 7143通用料箱 | BQ5: 6-100 | BR5: ○ | BS5: ◎
A6: 模具名称 | I6: 切边整形模 | AD6: 上压板形式及数量 | AS6: 12 | BD6: 自动 | BH6: 6-300 | BK6: OP60 | BL6: CBF4（左、右） | BN6: 空工位 | BO6: / | BQ6: 6-200 | BR6: ○ | BS6: ◎
A7: 模具总重量 | I7: 39 | AB7: T | AD7: 下压板形式及数量 | AS7: 4 | BD7: 手动 | BH7: 5-100 | BK7: OP70 | BL7: CBF5（左、右） | BN7: 二次拉伸模 | BQ7: 6-300 | BR7: ○ | BS7: ◎
A8: 上模重量 | I8: 20 | AB8: T | AD8: 撑头形式及数量 | AS8: 8 | BD8: 硬支撑 | BH8: 5-200 | BL8: CBF6（左、右） | BN8: 切边整形模 | BQ8: MEB-100/200 | BR8: ○ | BS8: ◎
A9: 闭合高度 | I9: 1274 | S9: ±2 | AB9: mm | AD9: 使用压机吨位 | AF9: / | AS9: 1200 | BD9: T | BH9: 4-100 | BN9: 翻边整形模 | BQ9: 7-200 | BR9: ○ | BS9: ◎
A10: 装模高度 | I10: 1350 | S10: ±5 | AB10: mm | AD10: 压机平衡缸压力 | AS10: / | BD10: Bar | BN10: 切边冲孔模
G11: -7 | I11: -6 | K11: -5 | M11: -4 | O11: -3 | Q11: -2 | S11: -1 | U11: 0 | V11: 1 | X11: 2 | Z11: 3 | AB11: 4 | AD11: 5 | AF11: 6 | AH11: 7 | AU11: 图例 | AX11: ◎ | AY11: 定位销 | BN11: 组合模
M12: ○ | AC12: ○ | AX12: ○ | AY12: 定位销孔
B13: 定位销分布图 | J13: ◎ | K13: ○ | L13: ○ | M13: ○ | N13: =IF(VLOOKUP($AZ$2,$BQ$2:$BT$9,4,0)=0,"",VLOOKUP($AZ$2,$BQ$2:$BT$9,4,0)) | O13: ○ | P13: ○ | Q13: =IF(VLOOKUP($AZ$2,$BQ$2:$BT$9,4,0)=0,"",VLOOKUP($AZ$2,$BQ$2:$BT$9,4,0)) | Y13: =IF(VLOOKUP($AZ$2,$BQ$2:$BT$9,4,0)=0,"",VLOOKUP($AZ$2,$BQ$2:$BT$9,4,0)) | Z13: ○ | AA13: ○ | AB13: =IF(VLOOKUP($AZ$2,$BQ$2:$BT$9,4,0)=0,"",VLOOKUP($AZ$2,$BQ$2:$BT$9,4,0)) | AC13: ○ | AD13: ○ | AE13: ○ | AF13: ◎
J14: ○ | L14: =IF(VLOOKUP($AZ$2,$BQ$2:$BT$9,4,0)=0,"",VLOOKUP($AZ$2,$BQ$2:$BT$9,4,0)) | M14: =IF(VLOOKUP($AZ$2,$BQ$2:$BT$9,4,0)=0,"",VLOOKUP($AZ$2,$BQ$2:$BT$9,4,0)) | N14: =IF(VLOOKUP($AZ$2,$BQ$2:$BT$9,4,0)=0,"",VLOOKUP($AZ$2,$BQ$2:$BT$9,4,0)) | O14: =IF(VLOOKUP($AZ$2,$BQ$2:$BT$9,4,0)=0,"",VLOOKUP($AZ$2,$BQ$2:$BT$9,4,0)) | P14: ○ | Q14: =IF(VLOOKUP($AZ$2,$BQ$2:$BT$9,4,0)=0,"",VLOOKUP($AZ$2,$BQ$2:$BT$9,4,0)) | T14: ○ | V14: ○ | Y14: =IF(VLOOKUP($AZ$2,$BQ$2:$BT$9,4,0)=0,"",VLOOKUP($AZ$2,$BQ$2:$BT$9,4,0)) | Z14: ○ | AA14: =IF(VLOOKUP($AZ$2,$BQ$2:$BT$9,4,0)=0,"",VLOOKUP($AZ$2,$BQ$2:$BT$9,4,0)) | AB14: =IF(VLOOKUP($AZ$2,$BQ$2:$BT$9,4,0)=0,"",VLOOKUP($AZ$2,$BQ$2:$BT$9,4,0)) | AC14: =IF(VLOOKUP($AZ$2,$BQ$2:$BT$9,4,0)=0,"",VLOOKUP($AZ$2,$BQ$2:$BT$9,4,0)) | AD14: =IF(VLOOKUP($AZ$2,$BQ$2:$BT$9,4,0)=0,"",VLOOKUP($AZ$2,$BQ$2:$BT$9,4,0)) | AF14: =IF(VLOOKUP($AZ$2,$BQ$2:$BT$9,2,0)=0,"",VLOOKUP($AZ$2,$BQ$2:$BT$9,2,0)) -> ○
AM16: ↑
AM19: 送料方向
J24: ○ | L24: =IF(VLOOKUP($AZ$2,$BQ$2:$BT$9,4,0)=0,"",VLOOKUP($AZ$2,$BQ$2:$BT$9,4,0)) | M24: =IF(VLOOKUP($AZ$2,$BQ$2:$BT$9,4,0)=0,"",VLOOKUP($AZ$2,$BQ$2:$BT$9,4,0)) | N24: =IF(VLOOKUP($AZ$2,$BQ$2:$BT$9,4,0)=0,"",VLOOKUP($AZ$2,$BQ$2:$BT$9,4,0)) | O24: =IF(VLOOKUP($AZ$2,$BQ$2:$BT$9,4,0)=0,"",VLOOKUP($AZ$2,$BQ$2:$BT$9,4,0)) | P24: ○ | Q24: =IF(VLOOKUP($AZ$2,$BQ$2:$BT$9,4,0)=0,"",VLOOKUP($AZ$2,$BQ$2:$BT$9,4,0)) | T24: ○ | V24: ○ | Y24: =IF(VLOOKUP($AZ$2,$BQ$2:$BT$9,4,0)=0,"",VLOOKUP($AZ$2,$BQ$2:$BT$9,4,0)) | Z24: ○ | AA24: =IF(VLOOKUP($AZ$2,$BQ$2:$BT$9,4,0)=0,"",VLOOKUP($AZ$2,$BQ$2:$BT$9,4,0)) | AB24: =IF(VLOOKUP($AZ$2,$BQ$2:$BT$9,4,0)=0,"",VLOOKUP($AZ$2,$BQ$2:$BT$9,4,0)) | AC24: =IF(VLOOKUP($AZ$2,$BQ$2:$BT$9,4,0)=0,"",VLOOKUP($AZ$2,$BQ$2:$BT$9,4,0)) | AD24: =IF(VLOOKUP($AZ$2,$BQ$2:$BT$9,4,0)=0,"",VLOOKUP($AZ$2,$BQ$2:$BT$9,4,0)) | AF24: ○
J25: ◎ | K25: ○ | L25: ○ | M25: ○ | N25: =IF(VLOOKUP($AZ$2,$BQ$2:$BT$9,4,0)=0,"",VLOOKUP($AZ$2,$BQ$2:$BT$9,4,0)) | O25: ○ | P25: ○ | Q25: =IF(VLOOKUP($AZ$2,$BQ$2:$BT$9,4,0)=0,"",VLOOKUP($AZ$2,$BQ$2:$BT$9,4,0)) | Y25: =IF(VLOOKUP($AZ$2,$BQ$2:$BT$9,4,0)=0,"",VLOOKUP($AZ$2,$BQ$2:$BT$9,4,0)) | Z25: ○ | AA25: ○ | AB25: =IF(VLOOKUP($AZ$2,$BQ$2:$BT$9,4,0)=0,"",VLOOKUP($AZ$2,$BQ$2:$BT$9,4,0)) | AC25: ○ | AD25: ○ | AE25: ○ | AF25: ◎
M26: ○ | AC26: ○
G27: -7 | I27: -6 | K27: -5 | M27: -4 | O27: -3 | Q27: -2 | S27: -1 | U27: 0 | V27: 1 | X27: 2 | Z27: 3 | AB27: 4 | AD27: 5 | AF27: 6 | AH27: 7
H28: -13 | I28: -12 | J28: -11 | K28: -10 | L28: -9 | M28: -8 | N28: -7 | O28: -6 | P28: -5 | Q28: -4 | R28: -3 | S28: -2 | T28: -1 | U28: 0 | V28: 1 | W28: 2 | X28: 3 | Y28: 4 | Z28: 5 | AA28: 6 | AB28: 7 | AC28: 8 | AD28: 9 | AE28: 10 | AF28: 11 | AG28: 12 | AH28: 13 | AV28: 图例 | BA28: ● | BB28: 顶棒
BA29: ○ | BB29: 顶棒孔
F30: 6 | H30: ○ | I30: ○ | J30: ○ | K30: ○ | L30: ○ | M30: ○ | N30: ○ | O30: ○ | P30: ○ | Q30: ○ | R30: ○ | S30: ○ | T30: ○ | U30: ○ | V30: ○ | W30: ○ | X30: ○ | Y30: ○ | Z30: ○ | AA30: ○ | AB30: ○ | AC30: ○ | AD30: ○ | AE30: ○ | AF30: ○ | AG30: ○ | AH30: ○ | AJ30: 6
B31: 滑块气垫顶棒分布图 | F31: 5 | H31: ○ | I31: ○ | J31: ○ | K31: ○ | L31: ● | M31: ○ | N31: ○ | O31: ○ | P31: ○ | Q31: ○ | R31: ○ | S31: ○ | T31: ● | U31: ○ | V31: ● | W31: ○ | X31: ● | Y31: ○ | Z31: ● | AA31: ○ | AB31: ● | AC31: ○ | AD31: ● | AE31: ○ | AF31: ○ | AG31: ○ | AH31: ○ | AJ31: 5
F32: 4 | H32: ○ | I32: ○ | J32: ○ | K32: ○ | L32: ○ | M32: ○ | N32: ○ | O32: ○ | P32: ○ | Q32: ○ | R32: ● | S32: ● | T32: ○ | U32: ○ | V32: ○ | W32: ○ | X32: ○ | Y32: ○ | Z32: ○ | AA32: ○ | AB32: ○ | AC32: ○ | AD32: ○ | AE32: ● | AF32: ○ | AG32: ○ | AH32: ○ | AJ32: 4
F33: 3 | H33: ○ | I33: ○ | J33: ○ | K33: ○ | L33: ○ | M33: ○ | N33: ○ | O33: ○ | P33: ○ | Q33: ○ | R33: ● | S33: ○ | T33: ○ | U33: ○ | V33: ○ | W33: ○ | X33: ○ | Y33: ○ | Z33: ○ | AA33: ○ | AB33: ○ | AC33: ○ | AD33: ○ | AE33: ○ | AF33: ● | AG33: ● | AH33: ○ | AJ33: 3
F34: 2 | H34: ○ | I34: ○ | J34: ○ | K34: ○ | L34: ○ | M34: ● | N34: ○ | O34: ○ | P34: ○ | Q34: ● | R34: ○ | S34: ○ | T34: ○ | U34: ● | V34: ○ | W34: ○ | X34: ○ | Y34: ○ | Z34: ○ | AA34: ● | AB34: ○ | AC34: ○ | AD34: ○ | AE34: ● | AF34: ○ | AG34: ○ | AH34: ○ | AJ34: 2
F35: 1 | H35: ○ | I35: ○ | J35: ○ | K35: ○ | L35: ● | M35: ● | N35: ○ | O35: ● | P35: ● | Q35: ○ | R35: ○ | S35: ○ | T35: ○ | U35: ○ | V35: ○ | W35: ○ | X35: ○ | Y35: ○ | Z35: ○ | AA35: ○ | AB35: ○ | AC35: ○ | AD35: ○ | AE35: ● | AF35: ● | AG35: ○ | AH35: ○ | AJ35: 1
F36: 0 | H36: ○ | I36: ○ | J36: ○ | K36: ○ | L36: ○ | M36: ● | N36: ● | O36: ○ | P36: ○ | Q36: ○ | R36: ○ | S36: ○ | T36: ○ | U36: ○ | V36: ○ | W36: ○ | X36: ○ | Y36: ○ | Z36: ○ | AA36: ○ | AB36: ○ | AC36: ○ | AD36: ○ | AE36: ● | AF36: ● | AG36: ○ | AH36: ○ | AJ36: 0
F37: -1 | H37: ○ | I37: ○ | J37: ○ | K37: ○ | L37: ● | M37: ● | N37: ○ | O37: ● | P37: ● | Q37: ○ | R37: ○ | S37: ○ | T37: ○ | U37: ○ | V37: ○ | W37: ○ | X37: ○ | Y37: ○ | Z37: ○ | AA37: ● | AB37: ○ | AC37: ○ | AD37: ○ | AE37: ○ | AF37: ● | AG37: ○ | AH37: ○ | AJ37: -1
F38: -2 | H38: ○ | I38: ○ | J38: ○ | K38: ○ | L38: ○ | M38: ○ | N38: ● | O38: ○ | P38: ○ | Q38: ○ | R38: ○ | S38: ○ | T38: ● | U38: ○ | V38: ○ | W38: ○ | X38: ○ | Y38: ○ | Z38: ○ | AA38: ○ | AB38: ○ | AC38: ○ | AD38: ● | AE38: ○ | AF38: ○ | AG38: ○ | AH38: ○ | AJ38: -2
F39: -3 | H39: ○ | I39: ○ | J39: ○ | K39: ○ | L39: ○ | M39: ○ | N39: ○ | O39: ○ | P39: ○ | Q39: ● | R39: ○ | S39: ○ | T39: ○ | U39: ○ | V39: ○ | W39: ○ | X39: ○ | Y39: ○ | Z39: ○ | AA39: ● | AB39: ● | AC39: ○ | AD39: ○ | AE39: ○ | AF39: ○ | AG39: ○ | AH39: ○ | AJ39: -3
F40: -4 | H40: ○ | I40: ○ | J40: ○ | K40: ○ | L40: ○ | M40: ○ | N40: ○ | O40: ○ | P40: ○ | Q40: ○ | R40: ● | S40: ● | T40: ● | U40: ● | V40: ● | W40: ● | X40: ● | Y40: ● | Z40: ○ | AA40: ○ | AB40: ○ | AC40: ○ | AD40: ○ | AE40: ○ | AF40: ○ | AG40: ○ | AH40: ○ | AJ40: -4 | AS40: 滑块顶棒数量 | AZ40: 48
F41: -5 | H41: ○ | I41: ○ | J41: ○ | K41: ○ | L41: ○ | M41: ○ | N41: ○ | O41: ○ | P41: ○ | Q41: ○ | R41: ○ | S41: ○ | T41: ○ | U41: ○ | V41: ○ | W41: ○ | X41: ○ | Y41: ○ | Z41: ○ | AA41: ○ | AB41: ○ | AC41: ○ | AD41: ○ | AE41: ○ | AF41: ○ | AG41: ○ | AH41: ○ | AJ41: -5
F42: -6 | H42: ○ | I42: ○ | J42: ○ | K42: ○ | L42: ○ | M42: ○ | N42: ○ | O42: ○ | P42: ○ | Q42: ○ | R42: ○ | S42: ○ | T42: ○ | U42: ○ | V42: ○ | W42: ○ | X42: ○ | Y42: ○ | Z42: ○ | AA42: ○ | AB42: ○ | AC42: ○ | AD42: ○ | AE42: ○ | AF42: ○ | AG42: ○ | AH42: ○ | AJ42: -6 | AS42: 滑块气垫压力 | AZ42: 1200
H43: -13 | I43: -12 | J43: -11 | K43: -10 | L43: -9 | M43: -8 | N43: -7 | O43: -6 | P43: -5 | Q43: -4 | R43: -3 | S43: -2 | T43: -1 | U43: 0 | V43: 1 | W43: 2 | X43: 3 | Y43: 4 | Z43: 5 | AA43: 6 | AB43: 7 | AC43: 8 | AD43: 9 | AE43: 10 | AF43: 11 | AG43: 12 | AH43: 13 | AS43: （± 50KN）
A44: 本工序使用的工装 | AD44: 备注
A45: 上料手 | D45: =I3 -> 11A 809 605 | O45: CBF1（左、右） | AD45: 1.巡视操作人数 1-2 人
A46: 下料手 | D46: =I3 -> 11A 809 605 | O46: CBF2（左、右）
A48: 本工序的操作方法
...

Sheet 单动-高速压机OP40
A1: PFS 冲压件工艺卡 | AS1: 版本 | AZ1: 1.2
AS2: 生产线 | AZ2: MEB-100/200 | BH2: MEB-100/200 | BI2: ● | BJ2: 舒勒 | BK2: OP20 | BL2: CBF0（左、右） | BM2: （± 50KN） | BN2: 切边模 | BO2: 专用料架 | BP2: KN | BQ2: 4-100 | BR2: ○ | BS2: ◎
A3: 零件号 | I3: ='（单动-高速压机OP20）'!I3:O3 -> 11A 809 605 | P3: 零件名称 | W3: ='（单动-高速压机OP20）'!W3:AC3 -> 左侧围外板 | AD3: 适用车型 | AL3: ='（单动-高速压机OP20）'!AL3:AR3 -> A SUVe | AS3: 工序号 | AZ3: OP40 | BH3: 7-200 | BI3: ○ | BJ3: 济二 | BK3: OP30 | BL3: CBF1（左、右） | BM3: （± 0.2Mpa） | BN3: 翻边模 | BO3: 7V1通用料箱 | BP3: Bar | BQ3: 5-100 | BR3: ○ | BS3: ◎
A4: 本工序模具参数 | BH4: 6-100 | BI4: ◎ | BK4: OP40 | BL4: CBF2（左、右） | BN4: 整形模 | BO4: 7V2通用料箱 | BQ4: 5-200 | BR4: ○ | BS4: ◎
A5: 模具编号 | I5: 78-72D-058005 | AD5: 压机 形式 | AS5: 舒勒 | BH5: 6-200 | BK5: OP50 | BL5: CBF3（左、右） | BN5: 冲孔模 | BO5: 7143通用料箱 | BQ5: 6-100 | BR5: ○ | BS5: ◎
A6: 模具名称 | I6: 翻边整形模 | AD6: 上压板形式及数量 | AS6: 12 | BD6: 自动 | BH6: 6-300 | BK6: OP60 | BL6: CBF4（左、右） | BN6: 空工位 | BO6: / | BQ6: 6-200 | BR6: ○ | BS6: ◎
A7: 模具总重量 | I7: 39.2 | AB7: T | AD7: 下压板形式及数量 | AS7: 4 | BD7: 手动 | BH7: 5-100 | BK7: OP70 | BL7: CBF5（左、右） | BN7: 二次拉伸模 | BQ7: 6-300 | BR7: ○ | BS7: ◎
A8: 上模重量 | I8: 19.3 | AB8: T | AD8: 撑头形式及数量 | AS8: 8 | BD8: 硬支撑 | BH8: 5-200 | BL8: CBF6（左、右） | BN8: 切边冲孔模 | BQ8: 7-100 | BR8: ○ | BS8: ◎
A9: 闭合高度 | I9: 1274.5 | S9: ±1.5 | AB9: mm | AD9: 使用压机吨位 | AF9: / | AS9: 1200 | BD9: T | BH9: 4-100 | BN9: 翻边整形模 | BQ9: MEB-100/200 | BR9: ○ | BS9: ◎
A10: 装模高度 | I10: 1350 | S10: ±5 | AB10: mm | AD10: 压机平衡缸压力 | AS10: / | BD10: Bar | BN10: 翻边冲孔模
G11: -7 | I11: -6 | K11: -5 | M11: -4 | O11: -3 | Q11: -2 | S11: -1 | U11: 0 | V11: 1 | X11: 2 | Z11: 3 | AB11: 4 | AD11: 5 | AF11: 6 | AH11: 7 | AU11: 图例 | AX11: ◎ | AY11: 定位销 | BN11: 组合模
M12: ○ | AC12: ○ | AX12: ○ | AY12: 定位销孔
B13: 定位销分布图 | J13: ◎ | K13: ○ | L13: ○ | M13: ○ | N13: =IF(VLOOKUP($AZ$2,$BQ$2:$BT$9,4,0)=0,"",VLOOKUP($AZ$2,$BQ$2:$BT$9,4,0)) | O13: ○ | P13: ○ | Q13: =IF(VLOOKUP($AZ$2,$BQ$2:$BT$9,4,0)=0,"",VLOOKUP($AZ$2,$BQ$2:$BT$9,4,0)) | Y13: =IF(VLOOKUP($AZ$2,$BQ$2:$BT$9,4,0)=0,"",VLOOKUP($AZ$2,$BQ$2:$BT$9,4,0)) | Z13: ○ | AA13: ○ | AB13: =IF(VLOOKUP($AZ$2,$BQ$2:$BT$9,4,0)=0,"",VLOOKUP($AZ$2,$BQ$2:$BT$9,4,0)) | AC13: ○ | AD13: ○ | AE13: ○ | AF13: ◎
J14: ○ | L14: =IF(VLOOKUP($AZ$2,$BQ$2:$BT$9,4,0)=0,"",VLOOKUP($AZ$2,$BQ$2:$BT$9,4,0)) | M14: =IF(VLOOKUP($AZ$2,$BQ$2:$BT$9,4,0)=0,"",VLOOKUP($AZ$2,$BQ$2:$BT$9,4,0)) | N14: =IF(VLOOKUP($AZ$2,$BQ$2:$BT$9,4,0)=0,"",VLOOKUP($AZ$2,$BQ$2:$BT$9,4,0)) | O14: =IF(VLOOKUP($AZ$2,$BQ$2:$BT$9,4,0)=0,"",VLOOKUP($AZ$2,$BQ$2:$BT$9,4,0)) | P14: ○ | Q14: =IF(VLOOKUP($AZ$2,$BQ$2:$BT$9,4,0)=0,"",VLOOKUP($AZ$2,$BQ$2:$BT$9,4,0)) | T14: ○ | V14: ○ | Y14: =IF(VLOOKUP($AZ$2,$BQ$2:$BT$9,4,0)=0,"",VLOOKUP($AZ$2,$BQ$2:$BT$9,4,0)) | Z14: ○ | AA14: =IF(VLOOKUP($AZ$2,$BQ$2:$BT$9,4,0)=0,"",VLOOKUP($AZ$2,$BQ$2:$BT$9,4,0)) | AB14: =IF(VLOOKUP($AZ$2,$BQ$2:$BT$9,4,0)=0,"",VLOOKUP($AZ$2,$BQ$2:$BT$9,4,0)) | AC14: =IF(VLOOKUP($AZ$2,$BQ$2:$BT$9,4,0)=0,"",VLOOKUP($AZ$2,$BQ$2:$BT$9,4,0)) | AD14: =IF(VLOOKUP($AZ$2,$BQ$2:$BT$9,4,0)=0,"",VLOOKUP($AZ$2,$BQ$2:$BT$9,4,0)) | AF14: =IF(VLOOKUP($AZ$2,$BQ$2:$BT$9,2,0)=0,"",VLOOKUP($AZ$2,$BQ$2:$BT$9,2,0)) -> ○
AM16: ↑
AM19: 送料方向
J24: ○ | L24: =IF(VLOOKUP($AZ$2,$BQ$2:$BT$9,4,0)=0,"",VLOOKUP($AZ$2,$BQ$2:$BT$9,4,0)) | M24: =IF(VLOOKUP($AZ$2,$BQ$2:$BT$9,4,0)=0,"",VLOOKUP($AZ$2,$BQ$2:$BT$9,4,0)) | N24: =IF(VLOOKUP($AZ$2,$BQ$2:$BT$9,4,0)=0,"",VLOOKUP($AZ$2,$BQ$2:$BT$9,4,0)) | O24: =IF(VLOOKUP($AZ$2,$BQ$2:$BT$9,4,0)=0,"",VLOOKUP($AZ$2,$BQ$2:$BT$9,4,0)) | P24: ○ | Q24: =IF(VLOOKUP($AZ$2,$BQ$2:$BT$9,4,0)=0,"",VLOOKUP($AZ$2,$BQ$2:$BT$9,4,0)) | T24: ○ | V24: ○ | Y24: =IF(VLOOKUP($AZ$2,$BQ$2:$BT$9,4,0)=0,"",VLOOKUP($AZ$2,$BQ$2:$BT$9,4,0)) | Z24: ○ | AA24: =IF(VLOOKUP($AZ$2,$BQ$2:$BT$9,4,0)=0,"",VLOOKUP($AZ$2,$BQ$2:$BT$9,4,0)) | AB24: =IF(VLOOKUP($AZ$2,$BQ$2:$BT$9,4,0)=0,"",VLOOKUP($AZ$2,$BQ$2:$BT$9,4,0)) | AC24: =IF(VLOOKUP($AZ$2,$BQ$2:$BT$9,4,0)=0,"",VLOOKUP($AZ$2,$BQ$2:$BT$9,4,0)) | AD24: =IF(VLOOKUP($AZ$2,$BQ$2:$BT$9,4,0)=0,"",VLOOKUP($AZ$2,$BQ$2:$BT$9,4,0)) | AF24: ○
J25: ◎ | K25: ○ | L25: ○ | M25: ○ | N25: =IF(VLOOKUP($AZ$2,$BQ$2:$BT$9,4,0)=0,"",VLOOKUP($AZ$2,$BQ$2:$BT$9,4,0)) | O25: ○ | P25: ○ | Q25: =IF(VLOOKUP($AZ$2,$BQ$2:$BT$9,4,0)=0,"",VLOOKUP($AZ$2,$BQ$2:$BT$9,4,0)) | Y25: =IF(VLOOKUP($AZ$2,$BQ$2:$BT$9,4,0)=0,"",VLOOKUP($AZ$2,$BQ$2:$BT$9,4,0)) | Z25: ○ | AA25: ○ | AB25: =IF(VLOOKUP($AZ$2,$BQ$2:$BT$9,4,0)=0,"",VLOOKUP($AZ$2,$BQ$2:$BT$9,4,0)) | AC25: ○ | AD25: ○ | AE25: ○ | AF25: ◎
M26: ○ | AC26: ○
G27: -7 | I27: -6 | K27: -5 | M27: -4 | O27: -3 | Q27: -2 | S27: -1 | U27: 0 | V27: 1 | X27: 2 | Z27: 3 | AB27: 4 | AD27: 5 | AF27: 6 | AH27: 7
H28: -13 | I28: -12 | J28: -11 | K28: -10 | L28: -9 | M28: -8 | N28: -7 | O28: -6 | P28: -5 | Q28: -4 | R28: -3 | S28: -2 | T28: -1 | U28: 0 | V28: 1 | W28: 2 | X28: 3 | Y28: 4 | Z28: 5 | AA28: 6 | AB28: 7 | AC28: 8 | AD28: 9 | AE28: 10 | AF28: 11 | AG28: 12 | AH28: 13 | AV28: 图例 | BA28: ● | BB28: 顶棒
G29: 6 | H29: ○ | I29: ○ | J29: ○ | K29: ○ | L29: ○ | M29: ○ | N29: ○ | O29: ○ | P29: ○ | Q29: ○ | R29: ○ | S29: ○ | T29: ○ | U29: ○ | V29: ○ | W29: ○ | X29: ○ | Y29: ○ | Z29: ○ | AA29: ○ | AB29: ○ | AC29: ○ | AD29: ○ | AE29: ○ | AF29: ○ | AG29: ○ | AH29: ○ | AI29: 6 | BA29: ○ | BB29: 顶棒孔
G30: 5 | H30: ○ | I30: ○ | J30: ○ | K30: ○ | L30: ○ | M30: ○ | N30: ○ | O30: ○ | P30: ○ | Q30: ○ | R30: ○ | S30: ● | T30: ○ | U30: ● | V30: ○ | W30: ● | X30: ● | Y30: ○ | Z30: ● | AA30: ○ | AB30: ● | AC30: ● | AD30: ○ | AE30: ○ | AF30: ○ | AG30: ○ | AH30: ○ | AI30: 5
B31: 滑块气垫顶棒分布图 | G31: 4 | H31: ○ | I31: ○ | J31: ○ | K31: ○ | L31: ○ | M31: ○ | N31: ○ | O31: ● | P31: ○ | Q31: ○ | R31: ○ | S31: ● | T31: ○ | U31: ○ | V31: ○ | W31: ○ | X31: ○ | Y31: ○ | Z31: ○ | AA31: ○ | AB31: ○ | AC31: ○ | AD31: ● | AE31: ○ | AF31: ○ | AG31: ○ | AH31: ○ | AI31: 4
G32: 3 | H32: ○ | I32: ○ | J32: ○ | K32: ○ | L32: ○ | M32: ○ | N32: ○ | O32: ○ | P32: ○ | Q32: ○ | R32: ● | S32: ○ | T32: ○ | U32: ● | V32: ○ | W32: ○ | X32: ○ | Y32: ○ | Z32: ○ | AA32: ○ | AB32: ○ | AC32: ● | AD32: ● | AE32: ○ | AF32: ○ | AG32: ○ | AH32: ○ | AI32: 3
G33: 2 | H33: ○ | I33: ○ | J33: ○ | K33: ○ | L33: ○ | M33: ○ | N33: ● | O33: ○ | P33: ○ | Q33: ● | R33: ● | S33: ○ | T33: ○ | U33: ○ | V33: ○ | W33: ○ | X33: ○ | Y33: ○ | Z33: ○ | AA33: ○ | AB33: ○ | AC33: ○ | AD33: ○ | AE33: ● | AF33: ○ | AG33: ○ | AH33: ○ | AI33: 2
G34: 1 | H34: ○ | I34: ○ | J34: ○ | K34: ○ | L34: ○ | M34: ● | N34: ● | O34: ○ | P34: ● | Q34: ○ | R34: ○ | S34: ○ | T34: ○ | U34: ○ | V34: ○ | W34: ● | X34: ○ | Y34: ○ | Z34: ○ | AA34: ○ | AB34: ○ | AC34: ○ | AD34: ● | AE34: ● | AF34: ○ | AG34: ○ | AH34: ○ | AI34: 1
G35: 0 | H35: ○ | I35: ○ | J35: ○ | K35: ○ | L35: ○ | M35: ● | N35: ○ | O35: ○ | P35: ● | Q35: ○ | R35: ○ | S35: ○ | T35: ○ | U35: ○ | V35: ○ | W35: ○ | X35: ○ | Y35: ○ | Z35: ○ | AA35: ○ | AB35: ○ | AC35: ○ | AD35: ○ | AE35: ● | AF35: ○ | AG35: ○ | AH35: ○ | AI35: 0
G36: 1 | H36: ○ | I36: ○ | J36: ○ | K36: ● | L36: ● | M36: ● | N36: ● | O36: ○ | P36: ● | Q36: ○ | R36: ○ | S36: ○ | T36: ○ | U36: ○ | V36: ○ | W36: ● | X36: ○ | Y36: ○ | Z36: ○ | AA36: ○ | AB36: ● | AC36: ○ | AD36: ● | AE36: ○ | AF36: ○ | AG36: ○ | AH36: ○ | AI36: 1
G37: 2 | H37: ○ | I37: ○ | J37: ○ | K37: ● | L37: ○ | M37: ○ | N37: ● | O37: ○ | P37: ○ | Q37: ○ | R37: ○ | S37: ○ | T37: ○ | U37: ● | V37: ○ | W37: ○ | X37: ○ | Y37: ○ | Z37: ○ | AA37: ○ | AB37: ● | AC37: ○ | AD37: ○ | AE37: ○ | AF37: ○ | AG37: ○ | AH37: ○ | AI37: 2
G38: 3 | H38: ○ | I38: ○ | J38: ○ | K38: ○ | L38: ○ | M38: ○ | N38: ○ | O38: ○ | P38: ● | Q38: ○ | R38: ● | S38: ○ | T38: ● | U38: ○ | V38: ● | W38: ● | X38: ○ | Y38: ○ | Z38: ● | AA38: ○ | AB38: ○ | AC38: ○ | AD38: ○ | AE38: ○ | AF38: ○ | AG38: ○ | AH38: ○ | AI38: 3
G39: 4 | H39: ○ | I39: ○ | J39: ○ | K39: ○ | L39: ○ | M39: ○ | N39: ○ | O39: ○ | P39: ○ | Q39: ○ | R39: ○ | S39: ○ | T39: ○ | U39: ○ | V39: ○ | W39: ○ | X39: ○ | Y39: ○ | Z39: ○ | AA39: ○ | AB39: ○ | AC39: ○ | AD39: ○ | AE39: ○ | AF39: ○ | AG39: ○ | AH39: ○ | AI39: 4
G40: 5 | H40: ○ | I40: ○ | J40: ○ | K40: ○ | L40: ○ | M40: ○ | N40: ○ | O40: ○ | P40: ○ | Q40: ○ | R40: ○ | S40: ○ | T40: ○ | U40: ○ | V40: ○ | W40: ○ | X40: ○ | Y40: ○ | Z40: ○ | AA40: ○ | AB40: ○ | AC40: ○ | AD40: ○ | AE40: ○ | AF40: ○ | AG40: ○ | AH40: ○ | AI40: 5 | AS40: 滑块顶棒数量 | AZ40: 45
G41: 6 | H41: ○ | I41: ○ | J41: ○ | K41: ○ | L41: ○ | M41: ○ | N41: ○ | O41: ○ | P41: ○ | Q41: ○ | R41: ○ | S41: ○ | T41: ○ | U41: ○ | V41: ○ | W41: ○ | X41: ○ | Y41: ○ | Z41: ○ | AA41: ○ | AB41: ○ | AC41: ○ | AD41: ○ | AE41: ○ | AF41: ○ | AG41: ○ | AH41: ○ | AI41: 6
H42: -13 | I42: -12 | J42: -11 | K42: -10 | L42: -9 | M42: -8 | N42: -7 | O42: -6 | P42: -5 | Q42: -4 | R42: -3 | S42: 2 | T42: 1 | U42: 0 | V42: 1 | W42: 2 | X42: 3 | Y42: 4 | Z42: 5 | AA42: 6 | AB42: 7 | AC42: 8 | AD42: 9 | AE42: 10 | AF42: 11 | AG42: 12 | AH42: 13 | AS42: 滑块气垫压力 | AZ42: 1400
AS43: （± 50KN）
A44: 本工序使用的工装 | AD44: 备注
A45: 上料手 | D45: =I3 -> 11A 809 605 | O45: CBF2（左、右） | AD45: 1.巡视操作人数 1-2 人
A46: 下料手 | D46: =I3 -> 11A 809 605 | O46: CBF3（左、右）
A48: 本工序的操作方法
...

Sheet 单动-高速压机OP50
A1: PFS 冲压件工艺卡 | AS1: 版本 | AZ1: 1.1
AS2: 生产线 | AZ2: MEB-100/200 | BH2: MEB-100/200 | BI2: ● | BJ2: 舒勒 | BK2: OP20 | BL2: CBF0（左、右） | BM2: （± 50KN） | BN2: 切边模 | BO2: 专用料架 | BP2: KN | BQ2: 4-100 | BR2: ○ | BS2: ◎
A3: 零件号 | I3: ='（单动-高速压机OP20）'!I3:O3 -> 11A 809 605 | P3: 零件名称 | W3: ='（单动-高速压机OP20）'!W3:AC3 -> 左侧围外板 | AD3: 适用车型 | AL3: ='（单动-高速压机OP20）'!AL3:AR3 -> A SUVe | AS3: 工序号 | AZ3: OP50 | BH3: 7-200 | BI3: ○ | BJ3: 济二 | BK3: OP30 | BL3: CBF1（左、右） | BM3: （± 0.2Mpa） | BN3: 翻边模 | BO3: 7V1通用料箱 | BP3: Bar | BQ3: 5-100 | BR3: ○ | BS3: ◎
A4: 本工序模具参数 | BH4: 6-100 | BI4: ◎ | BK4: OP40 | BL4: CBF2（左、右） | BN4: 整形模 | BO4: 7V2通用料箱 | BQ4: 5-200 | BR4: ○ | BS4: ◎
A5: 模具编号 | I5: 78-72D-058007 | AD5: 压机 形式 | AS5: 舒勒 | BH5: 6-200 | BK5: OP50 | BL5: CBF3（左、右） | BN5: 冲孔模 | BO5: 7143通用料箱 | BQ5: 6-100 | BR5: ○ | BS5: ◎
A6: 模具名称 | I6: 切边整形冲孔模 | AD6: 上压板形式及数量 | AS6: 12 | BD6: 自动 | BH6: 6-300 | BK6: OP60 | BL6: CBF4（左、右） | BN6: 空工位 | BO6: / | BQ6: 6-200 | BR6: ○ | BS6: ◎
A7: 模具总重量 | I7: 36.5 | AB7: T | AD7: 下压板形式及数量 | AS7: 4 | BD7: 手动 | BH7: 5-100 | BK7: OP70 | BL7: CBF5（左、右） | BN7: 二次拉伸模 | BQ7: 6-300 | BR7: ○ | BS7: ◎
A8: 上模重量 | I8: 16.5 | AB8: T | AD8: 撑头形式及数量 | AS8: 8 | BD8: 硬支撑 | BH8: 5-200 | BL8: CBF6（左、右） | BN8: 切边整形冲孔模 | BQ8: MEB-100 | BR8: ○ | BS8: ◎
A9: 闭合高度 | I9: 1276 | S9: ±1.5 | AB9: mm | AD9: 使用压机吨位 | AF9: / | AS9: 1200 | BD9: T | BH9: 4-100 | BN9: 翻边整形模 | BQ9: MEB-100/200 | BR9: ○ | BS9: ◎
A10: 装模高度 | I10: 1350 | S10: ±5 | AB10: mm | AD10: 压机平衡缸压力 | AS10: / | BD10: Bar | BN10: 翻边冲孔模
G11: -7 | I11: -6 | K11: -5 | M11: -4 | O11: -3 | Q11: -2 | S11: -1 | U11: 0 | V11: 1 | X11: 2 | Z11: 3 | AB11: 4 | AD11: 5 | AF11: 6 | AH11: 7 | AU11: 图例 | AX11: ◎ | AY11: 定位销 | BN11: 组合模
M12: ○ | AC12: ○ | AX12: ○ | AY12: 定位销孔
B13: 定位销分布图 | J13: ◎ | K13: ○ | L13: ○ | M13: ○ | N13: =IF(VLOOKUP($AZ$2,$BQ$2:$BT$9,4,0)=0,"",VLOOKUP($AZ$2,$BQ$2:$BT$9,4,0)) | O13: ○ | P13: ○ | Q13: =IF(VLOOKUP($AZ$2,$BQ$2:$BT$9,4,0)=0,"",VLOOKUP($AZ$2,$BQ$2:$BT$9,4,0)) | Y13: =IF(VLOOKUP($AZ$2,$BQ$2:$BT$9,4,0)=0,"",VLOOKUP($AZ$2,$BQ$2:$BT$9,4,0)) | Z13: ○ | AA13: ○ | AB13: =IF(VLOOKUP($AZ$2,$BQ$2:$BT$9,4,0)=0,"",VLOOKUP($AZ$2,$BQ$2:$BT$9,4,0)) | AC13: ○ | AD13: ○ | AE13: ○ | AF13: ◎
J14: ○ | L14: =IF(VLOOKUP($AZ$2,$BQ$2:$BT$9,4,0)=0,"",VLOOKUP($AZ$2,$BQ$2:$BT$9,4,0)) | M14: =IF(VLOOKUP($AZ$2,$BQ$2:$BT$9,4,0)=0,"",VLOOKUP($AZ$2,$BQ$2:$BT$9,4,0)) | N14: =IF(VLOOKUP($AZ$2,$BQ$2:$BT$9,4,0)=0,"",VLOOKUP($AZ$2,$BQ$2:$BT$9,4,0)) | O14: =IF(VLOOKUP($AZ$2,$BQ$2:$BT$9,4,0)=0,"",VLOOKUP($AZ$2,$BQ$2:$BT$9,4,0)) | P14: ○ | Q14: =IF(VLOOKUP($AZ$2,$BQ$2:$BT$9,4,0)=0,"",VLOOKUP($AZ$2,$BQ$2:$BT$9,4,0)) | T14: ○ | V14: ○ | Y14: =IF(VLOOKUP($AZ$2,$BQ$2:$BT$9,4,0)=0,"",VLOOKUP($AZ$2,$BQ$2:$BT$9,4,0)) | Z14: ○ | AA14: =IF(VLOOKUP($AZ$2,$BQ$2:$BT$9,4,0)=0,"",VLOOKUP($AZ$2,$BQ$2:$BT$9,4,0)) | AB14: =IF(VLOOKUP($AZ$2,$BQ$2:$BT$9,4,0)=0,"",VLOOKUP($AZ$2,$BQ$2:$BT$9,4,0)) | AC14: =IF(VLOOKUP($AZ$2,$BQ$2:$BT$9,4,0)=0,"",VLOOKUP($AZ$2,$BQ$2:$BT$9,4,0)) | AD14: =IF(VLOOKUP($AZ$2,$BQ$2:$BT$9,4,0)=0,"",VLOOKUP($AZ$2,$BQ$2:$BT$9,4,0)) | AF14: =IF(VLOOKUP($AZ$2,$BQ$2:$BT$9,2,0)=0,"",VLOOKUP($AZ$2,$BQ$2:$BT$9,2,0)) -> ○
AM16: ↑
AM19: 送料方向
J24: ○ | L24: =IF(VLOOKUP($AZ$2,$BQ$2:$BT$9,4,0)=0,"",VLOOKUP($AZ$2,$BQ$2:$BT$9,4,0)) | M24: =IF(VLOOKUP($AZ$2,$BQ$2:$BT$9,4,0)=0,"",VLOOKUP($AZ$2,$BQ$2:$BT$9,4,0)) | N24: =IF(VLOOKUP($AZ$2,$BQ$2:$BT$9,4,0)=0,"",VLOOKUP($AZ$2,$BQ$2:$BT$9,4,0)) | O24: =IF(VLOOKUP($AZ$2,$BQ$2:$BT$9,4,0)=0,"",VLOOKUP($AZ$2,$BQ$2:$BT$9,4,0)) | P24: ○ | Q24: =IF(VLOOKUP($AZ$2,$BQ$2:$BT$9,4,0)=0,"",VLOOKUP($AZ$2,$BQ$2:$BT$9,4,0)) | T24: ○ | V24: ○ | Y24: =IF(VLOOKUP($AZ$2,$BQ$2:$BT$9,4,0)=0,"",VLOOKUP($AZ$2,$BQ$2:$BT$9,4,0)) | Z24: ○ | AA24: =IF(VLOOKUP($AZ$2,$BQ$2:$BT$9,4,0)=0,"",VLOOKUP($AZ$2,$BQ$2:$BT$9,4,0)) | AB24: =IF(VLOOKUP($AZ$2,$BQ$2:$BT$9,4,0)=0,"",VLOOKUP($AZ$2,$BQ$2:$BT$9,4,0)) | AC24: =IF(VLOOKUP($AZ$2,$BQ$2:$BT$9,4,0)=0,"",VLOOKUP($AZ$2,$BQ$2:$BT$9,4,0)) | AD24: =IF(VLOOKUP($AZ$2,$BQ$2:$BT$9,4,0)=0,"",VLOOKUP($AZ$2,$BQ$2:$BT$9,4,0)) | AF24: ○
J25: ◎ | K25: ○ | L25: ○ | M25: ○ | N25: =IF(VLOOKUP($AZ$2,$BQ$2:$BT$9,4,0)=0,"",VLOOKUP($AZ$2,$BQ$2:$BT$9,4,0)) | O25: ○ | P25: ○ | Q25: =IF(VLOOKUP($AZ$2,$BQ$2:$BT$9,4,0)=0,"",VLOOKUP($AZ$2,$BQ$2:$BT$9,4,0)) | Y25: =IF(VLOOKUP($AZ$2,$BQ$2:$BT$9,4,0)=0,"",VLOOKUP($AZ$2,$BQ$2:$BT$9,4,0)) | Z25: ○ | AA25: ○ | AB25: =IF(VLOOKUP($AZ$2,$BQ$2:$BT$9,4,0)=0,"",VLOOKUP($AZ$2,$BQ$2:$BT$9,4,0)) | AC25: ○ | AD25: ○ | AE25: ○ | AF25: ◎
M26: ○ | AC26: ○
G27: -7 | I27: -6 | K27: -5 | M27: -4 | O27: -3 | Q27: -2 | S27: -1 | U27: 0 | V27: 1 | X27: 2 | Z27: 3 | AB27: 4 | AD27: 5 | AF27: 6 | AH27: 7
H28: -13 | I28: -12 | J28: -11 | K28: -10 | L28: -9 | M28: -8 | N28: -7 | O28: -6 | P28: -5 | Q28: -4 | R28: -3 | S28: -2 | T28: -1 | U28: 0 | V28: 1 | W28: 2 | X28: 3 | Y28: 4 | Z28: 5 | AA28: 6 | AB28: 7 | AC28: 8 | AD28: 9 | AE28: 10 | AF28: 11 | AG28: 12 | AH28: 13 | AV28: 图例 | BA28: ● | BB28: 顶棒
G29: 6 | H29: ○ | I29: ○ | J29: ○ | K29: ○ | L29: ○ | M29: ○ | N29: ○ | O29: ○ | P29: ○ | Q29: ○ | R29: ○ | S29: ○ | T29: ○ | U29: ○ | V29: ○ | W29: ○ | X29: ○ | Y29: ○ | Z29: ○ | AA29: ○ | AB29: ○ | AC29: ○ | AD29: ○ | AE29: ○ | AF29: ○ | AG29: ○ | AH29: ○ | AI29: 6 | BA29: ○ | BB29: 顶棒孔
G30: 5 | H30: ○ | I30: ○ | J30: ○ | K30: ○ | L30: ○ | M30: ○ | N30: ○ | O30: ○ | P30: ○ | Q30: ○ | R30: ○ | S30: ● | T30: ○ | U30: ○ | V30: ○ | W30: ● | X30: ○ | Y30: ○ | Z30: ○ | AA30: ● | AB30: ○ | AC30: ○ | AD30: ○ | AE30: ● | AF30: ○ | AG30: ○ | AH30: ○ | AI30: 5
B31: 滑块气垫顶棒分布图 | G31: 4 | H31: ○ | I31: ○ | J31: ○ | K31: ○ | L31: ○ | M31: ● | N31: ○ | O31: ○ | P31: ○ | Q31: ○ | R31: ○ | S31: ● | T31: ○ | U31: ● | V31: ○ | W31: ○ | X31: ○ | Y31: ● | Z31: ○ | AA31: ○ | AB31: ○ | AC31: ● | AD31: ○ | AE31: ○ | AF31: ○ | AG31: ○ | AH31: ○ | AI31: 4
G32: 3 | H32: ○ | I32: ○ | J32: ○ | K32: ○ | L32: ● | M32: ○ | N32: ○ | O32: ○ | P32: ○ | Q32: ○ | R32: ● | S32: ○ | T32: ● | U32: ○ | V32: ○ | W32: ● | X32: ○ | Y32: ○ | Z32: ○ | AA32: ○ | AB32: ○ | AC32: ○ | AD32: ● | AE32: ○ | AF32: ○ | AG32: ○ | AH32: ○ | AI32: 3
G33: 2 | H33: ○ | I33: ○ | J33: ○ | K33: ○ | L33: ● | M33: ● | N33: ● | O33: ○ | P33: ○ | Q33: ● | R33: ○ | S33: ○ | T33: ○ | U33: ○ | V33: ○ | W33: ○ | X33: ○ | Y33: ○ | Z33: ○ | AA33: ○ | AB33: ○ | AC33: ○ | AD33: ○ | AE33: ● | AF33: ○ | AG33: ○ | AH33: ○ | AI33: 2
G34: 1 | H34: ○ | I34: ○ | J34: ○ | K34: ○ | L34: ● | M34: ○ | N34: ○ | O34: ● | P34: ● | Q34: ○ | R34: ○ | S34: ○ | T34: ○ | U34: ○ | V34: ○ | W34: ● | X34: ○ | Y34: ○ | Z34: ○ | AA34: ○ | AB34: ● | AC34: ○ | AD34: ○ | AE34: ○ | AF34: ○ | AG34: ○ | AH34: ○ | AI34: 1
G35: 0 | H35: ○ | I35: ○ | J35: ○ | K35: ○ | L35: ○ | M35: ○ | N35: ○ | O35: ● | P35: ○ | Q35: ○ | R35: ○ | S35: ○ | T35: ○ | U35: ○ | V35: ○ | W35: ○ | X35: ○ | Y35: ○ | Z35: ○ | AA35: ○ | AB35: ○ | AC35: ○ | AD35: ○ | AE35: ● | AF35: ○ | AG35: ○ | AH35: ○ | AI35: 0
G36: 1 | H36: ○ | I36: ○ | J36: ○ | K36: ● | L36: ● | M36: ○ | N36: ○ | O36: ● | P36: ○ | Q36: ○ | R36: ● | S36: ○ | T36: ○ | U36: ○ | V36: ○ | W36: ● | X36: ○ | Y36: ● | Z36: ○ | AA36: ○ | AB36: ○ | AC36: ● | AD36: ● | AE36: ○ | AF36: ○ | AG36: ○ | AH36: ○ | AI36: 1
G37: 2 | H37: ○ | I37: ○ | J37: ○ | K37: ○ | L37: ○ | M37: ● | N37: ○ | O37: ● | P37: ○ | Q37: ● | R37: ○ | S37: ○ | T37: ○ | U37: ○ | V37: ○ | W37: ○ | X37: ○ | Y37: ○ | Z37: ○ | AA37: ● | AB37: ● | AC37: ○ | AD37: ○ | AE37: ○ | AF37: ○ | AG37: ○ | AH37: ○ | AI37: 2
G38: 3 | H38: ○ | I38: ○ | J38: ○ | K38: ○ | L38: ○ | M38: ○ | N38: ○ | O38: ● | P38: ● | Q38: ○ | R38: ○ | S38: ○ | T38: ○ | U38: ○ | V38: ○ | W38: ● | X38: ○ | Y38: ○ | Z38: ● | AA38: ○ | AB38: ○ | AC38: ○ | AD38: ○ | AE38: ○ | AF38: ○ | AG38: ○ | AH38: ○ | AI38: 3
G39: 4 | H39: ○ | I39: ○ | J39: ○ | K39: ○ | L39: ○ | M39: ○ | N39: ○ | O39: ○ | P39: ○ | Q39: ● | R39: ○ | S39: ○ | T39: ○ | U39: ○ | V39: ○ | W39: ● | X39: ○ | Y39: ○ | Z39: ○ | AA39: ○ | AB39: ○ | AC39: ○ | AD39: ○ | AE39: ○ | AF39: ○ | AG39: ○ | AH39: ○ | AI39: 4
G40: 5 | H40: ○ | I40: ○ | J40: ○ | K40: ○ | L40: ○ | M40: ○ | N40: ○ | O40: ○ | P40: ○ | Q40: ○ | R40: ○ | S40: ○ | T40: ○ | U40: ○ | V40: ○ | W40: ○ | X40: ○ | Y40: ○ | Z40: ○ | AA40: ○ | AB40: ○ | AC40: ○ | AD40: ○ | AE40: ○ | AF40: ○ | AG40: ○ | AH40: ○ | AI40: 5 | AS40: 滑块顶棒数量 | AZ40: 45
G41: 6 | H41: ○ | I41: ○ | J41: ○ | K41: ○ | L41: ○ | M41: ○ | N41: ○ | O41: ○ | P41: ○ | Q41: ○ | R41: ○ | S41: ○ | T41: ○ | U41: ○ | V41: ○ | W41: ○ | X41: ○ | Y41: ○ | Z41: ○ | AA41: ○ | AB41: ○ | AC41: ○ | AD41: ○ | AE41: ○ | AF41: ○ | AG41: ○ | AH41: ○ | AI41: 6
H42: -13 | I42: -12 | J42: -11 | K42: -10 | L42: -9 | M42: -8 | N42: -7 | O42: -6 | P42: -5 | Q42: -4 | R42: -3 | S42: 2 | T42: 1 | U42: 0 | V42: 1 | W42: 2 | X42: 3 | Y42: 4 | Z42: 5 | AA42: 6 | AB42: 7 | AC42: 8 | AD42: 9 | AE42: 10 | AF42: 11 | AG42: 12 | AH42: 13 | AS42: 滑块气垫压力 | AZ42: 1200
AS43: （± 50KN）
A44: 本工序使用的工装 | AD44: 备注
A45: 上料手 | D45: =I3 -> 11A 809 605 | O45: CBF3（左、右） | AD45: 1.巡视操作人数 1-2 人
A46: 下料手 | D46: =I3 -> 11A 809 605 | O46: CBF4（左、右）
A48: 本工序的操作方法
...

Sheet 单动-高速压机OP60
A1: PFS 冲压件工艺卡 | AS1: 版本 | AZ1: 1.1
AS2: 生产线 | AZ2: MEB-100/200 | BH2: MEB-100/200 | BI2: ● | BJ2: 舒勒 | BK2: OP20 | BL2: CBF0（左、右） | BM2: （± 50KN） | BN2: 切边模 | BO2: 专用料架 | BP2: KN | BQ2: 4-100 | BR2: ○ | BS2: ◎
A3: 零件号 | I3: ='（单动-高速压机OP20）'!I3:O3 -> 11A 809 605 | P3: 零件名称 | W3: ='（单动-高速压机OP20）'!W3:AC3 -> 左侧围外板 | AD3: 适用车型 | AL3: ='（单动-高速压机OP20）'!AL3:AR3 -> A SUVe | AS3: 工序号 | AZ3: OP60 | BH3: 7-200 | BI3: ○ | BJ3: 济二 | BK3: OP30 | BL3: CBF1（左、右） | BM3: （± 0.2Mpa） | BN3: 翻边模 | BO3: 7V1通用料箱 | BP3: Bar | BQ3: 5-100 | BR3: ○ | BS3: ◎
A4: 本工序模具参数 | BH4: 6-100 | BI4: ◎ | BK4: OP40 | BL4: CBF2（左、右） | BN4: 整形模 | BO4: 7V2通用料箱 | BQ4: 5-200 | BR4: ○ | BS4: ◎
A5: 模具编号 | I5: 78-72D-058009 | AD5: 压机 形式 | AS5: 舒勒 | BH5: 6-200 | BK5: OP50 | BL5: CBF3（左、右） | BN5: 冲孔模 | BO5: 7143通用料箱 | BQ5: 6-100 | BR5: ○ | BS5: ◎
A6: 模具名称 | I6: 切边整形冲孔模 | AD6: 上压板形式及数量 | AS6: 12 | BD6: 自动 | BH6: 6-300 | BK6: OP60 | BL6: CBF4（左、右） | BN6: 空工位 | BO6: / | BQ6: 6-200 | BR6: ○ | BS6: ◎
A7: 模具总重量 | I7: 36.4 | AB7: T | AD7: 下压板形式及数量 | AS7: 4 | BD7: 手动 | BH7: 5-100 | BK7: OP70 | BL7: CBF5（左、右） | BN7: 二次拉伸模 | BQ7: 6-300 | BR7: ○ | BS7: ◎
A8: 上模重量 | I8: 16.6 | AB8: T | AD8: 撑头形式及数量 | AS8: 8 | BD8: 硬支撑 | BH8: 5-200 | BL8: CBF6（左、右） | BN8: 切边整形冲孔模 | BQ8: MEB-100 | BR8: ○ | BS8: ◎
A9: 闭合高度 | I9: 1277 | S9: ±1.5 | AB9: mm | AD9: 使用压机吨位 | AF9: / | AS9: 1200 | BD9: T | BH9: 4-100 | BN9: 翻边整形模 | BQ9: MEB-100/200 | BR9: ○ | BS9: ◎
A10: 装模高度 | I10: 1350 | S10: ±5 | AB10: mm | AD10: 压机平衡缸压力 | AS10: / | BD10: Bar | BN10: 翻边冲孔模
G11: -7 | I11: -6 | K11: -5 | M11: -4 | O11: -3 | Q11: -2 | S11: -1 | U11: 0 | V11: 1 | X11: 2 | Z11: 3 | AB11: 4 | AD11: 5 | AF11: 6 | AH11: 7 | AU11: 图例 | AX11: ◎ | AY11: 定位销 | BN11: 组合模
M12: ○ | AC12: ○ | AX12: ○ | AY12: 定位销孔
B13: 定位销分布图 | J13: ◎ | K13: ○ | L13: ○ | M13: ○ | N13: =IF(VLOOKUP($AZ$2,$BQ$2:$BT$9,4,0)=0,"",VLOOKUP($AZ$2,$BQ$2:$BT$9,4,0)) | O13: ○ | P13: ○ | Q13: =IF(VLOOKUP($AZ$2,$BQ$2:$BT$9,4,0)=0,"",VLOOKUP($AZ$2,$BQ$2:$BT$9,4,0)) | Y13: =IF(VLOOKUP($AZ$2,$BQ$2:$BT$9,4,0)=0,"",VLOOKUP($AZ$2,$BQ$2:$BT$9,4,0)) | Z13: ○ | AA13: ○ | AB13: =IF(VLOOKUP($AZ$2,$BQ$2:$BT$9,4,0)=0,"",VLOOKUP($AZ$2,$BQ$2:$BT$9,4,0)) | AC13: ○ | AD13: ○ | AE13: ○ | AF13: ◎
J14: ○ | L14: =IF(VLOOKUP($AZ$2,$BQ$2:$BT$9,4,0)=0,"",VLOOKUP($AZ$2,$BQ$2:$BT$9,4,0)) | M14: =IF(VLOOKUP($AZ$2,$BQ$2:$BT$9,4,0)=0,"",VLOOKUP($AZ$2,$BQ$2:$BT$9,4,0)) | N14: =IF(VLOOKUP($AZ$2,$BQ$2:$BT$9,4,0)=0,"",VLOOKUP($AZ$2,$BQ$2:$BT$9,4,0)) | O14: =IF(VLOOKUP($AZ$2,$BQ$2:$BT$9,4,0)=0,"",VLOOKUP($AZ$2,$BQ$2:$BT$9,4,0)) | P14: ○ | Q14: =IF(VLOOKUP($AZ$2,$BQ$2:$BT$9,4,0)=0,"",VLOOKUP($AZ$2,$BQ$2:$BT$9,4,0)) | T14: ○ | V14: ○ | Y14: =IF(VLOOKUP($AZ$2,$BQ$2:$BT$9,4,0)=0,"",VLOOKUP($AZ$2,$BQ$2:$BT$9,4,0)) | Z14: ○ | AA14: =IF(VLOOKUP($AZ$2,$BQ$2:$BT$9,4,0)=0,"",VLOOKUP($AZ$2,$BQ$2:$BT$9,4,0)) | AB14: =IF(VLOOKUP($AZ$2,$BQ$2:$BT$9,4,0)=0,"",VLOOKUP($AZ$2,$BQ$2:$BT$9,4,0)) | AC14: =IF(VLOOKUP($AZ$2,$BQ$2:$BT$9,4,0)=0,"",VLOOKUP($AZ$2,$BQ$2:$BT$9,4,0)) | AD14: =IF(VLOOKUP($AZ$2,$BQ$2:$BT$9,4,0)=0,"",VLOOKUP($AZ$2,$BQ$2:$BT$9,4,0)) | AF14: =IF(VLOOKUP($AZ$2,$BQ$2:$BT$9,2,0)=0,"",VLOOKUP($AZ$2,$BQ$2:$BT$9,2,0)) -> ○
AM16: ↑
AM19: 送料方向
J24: ○ | L24: =IF(VLOOKUP($AZ$2,$BQ$2:$BT$9,4,0)=0,"",VLOOKUP($AZ$2,$BQ$2:$BT$9,4,0)) | M24: =IF(VLOOKUP($AZ$2,$BQ$2:$BT$9,4,0)=0,"",VLOOKUP($AZ$2,$BQ$2:$BT$9,4,0)) | N24: =IF(VLOOKUP($AZ$2,$BQ$2:$BT$9,4,0)=0,"",VLOOKUP($AZ$2,$BQ$2:$BT$9,4,0)) | O24: =IF(VLOOKUP($AZ$2,$BQ$2:$BT$9,4,0)=0,"",VLOOKUP($AZ$2,$BQ$2:$BT$9,4,0)) | P24: ○ | Q24: =IF(VLOOKUP($AZ$2,$BQ$2:$BT$9,4,0)=0,"",VLOOKUP($AZ$2,$BQ$2:$BT$9,4,0)) | T24: ○ | V24: ○ | Y24: =IF(VLOOKUP($AZ$2,$BQ$2:$BT$9,4,0)=0,"",VLOOKUP($AZ$2,$BQ$2:$BT$9,4,0)) | Z24: ○ | AA24: =IF(VLOOKUP($AZ$2,$BQ$2:$BT$9,4,0)=0,"",VLOOKUP($AZ$2,$BQ$2:$BT$9,4,0)) | AB24: =IF(VLOOKUP($AZ$2,$BQ$2:$BT$9,4,0)=0,"",VLOOKUP($AZ$2,$BQ$2:$BT$9,4,0)) | AC24: =IF(VLOOKUP($AZ$2,$BQ$2:$BT$9,4,0)=0,"",VLOOKUP($AZ$2,$BQ$2:$BT$9,4,0)) | AD24: =IF(VLOOKUP($AZ$2,$BQ$2:$BT$9,4,0)=0,"",VLOOKUP($AZ$2,$BQ$2:$BT$9,4,0)) | AF24: ○
J25: ◎ | K25: ○ | L25: ○ | M25: ○ | N25: =IF(VLOOKUP($AZ$2,$BQ$2:$BT$9,4,0)=0,"",VLOOKUP($AZ$2,$BQ$2:$BT$9,4,0)) | O25: ○ | P25: ○ | Q25: =IF(VLOOKUP($AZ$2,$BQ$2:$BT$9,4,0)=0,"",VLOOKUP($AZ$2,$BQ$2:$BT$9,4,0)) | Y25: =IF(VLOOKUP($AZ$2,$BQ$2:$BT$9,4,0)=0,"",VLOOKUP($AZ$2,$BQ$2:$BT$9,4,0)) | Z25: ○ | AA25: ○ | AB25: =IF(VLOOKUP($AZ$2,$BQ$2:$BT$9,4,0)=0,"",VLOOKUP($AZ$2,$BQ$2:$BT$9,4,0)) | AC25: ○ | AD25: ○ | AE25: ○ | AF25: ◎
M26: ○ | AC26: ○
G27: -7 | I27: -6 | K27: -5 | M27: -4 | O27: -3 | Q27: -2 | S27: -1 | U27: 0 | V27: 1 | X27: 2 | Z27: 3 | AB27: 4 | AD27: 5 | AF27: 6 | AH27: 7
H28: -13 | I28: -12 | J28: -11 | K28: -10 | L28: -9 | M28: -8 | N28: -7 | O28: -6 | P28: -5 | Q28: -4 | R28: -3 | S28: -2 | T28: -1 | U28: 0 | V28: 1 | W28: 2 | X28: 3 | Y28: 4 | Z28: 5 | AA28: 6 | AB28: 7 | AC28: 8 | AD28: 9 | AE28: 10 | AF28: 11 | AG28: 12 | AH28: 13 | AV28: 图例 | BA28: ● | BB28: 顶棒
G29: 6 | H29: ○ | I29: ○ | J29: ○ | K29: ○ | L29: ○ | M29: ○ | N29: ○ | O29: ○ | P29: ○ | Q29: ○ | R29: ○ | S29: ○ | T29: ○ | U29: ○ | V29: ○ | W29: ○ | X29: ○ | Y29: ○ | Z29: ○ | AA29: ○ | AB29: ○ | AC29: ○ | AD29: ○ | AE29: ○ | AF29: ○ | AG29: ○ | AH29: ○ | AI29: 6 | BA29: ○ | BB29: 顶棒孔
G30: 5 | H30: ○ | I30: ○ | J30: ○ | K30: ○ | L30: ○ | M30: ○ | N30: ○ | O30: ○ | P30: ○ | Q30: ○ | R30: ○ | S30: ○ | T30: ● | U30: ○ | V30: ○ | W30: ● | X30: ○ | Y30: ○ | Z30: ○ | AA30: ○ | AB30: ○ | AC30: ● | AD30: ○ | AE30: ○ | AF30: ○ | AG30: ○ | AH30: ○ | AI30: 5
B31: 滑块气垫顶棒分布图 | G31: 4 | H31: ○ | I31: ○ | J31: ○ | K31: ○ | L31: ○ | M31: ○ | N31: ○ | O31: ○ | P31: ○ | Q31: ○ | R31: ○ | S31: ● | T31: ○ | U31: ○ | V31: ○ | W31: ○ | X31: ○ | Y31: ○ | Z31: ● | AA31: ○ | AB31: ○ | AC31: ○ | AD31: ○ | AE31: ● | AF31: ○ | AG31: ○ | AH31: ○ | AI31: 4
G32: 3 | H32: ○ | I32: ○ | J32: ○ | K32: ○ | L32: ● | M32: ○ | N32: ● | O32: ○ | P32: ○ | Q32: ○ | R32: ○ | S32: ● | T32: ○ | U32: ○ | V32: ● | W32: ○ | X32: ● | Y32: ○ | Z32: ○ | AA32: ○ | AB32: ○ | AC32: ● | AD32: ● | AE32: ○ | AF32: ○ | AG32: ○ | AH32: ○ | AI32: 3
G33: 2 | H33: ○ | I33: ○ | J33: ○ | K33: ○ | L33: ○ | M33: ○ | N33: ○ | O33: ○ | P33: ○ | Q33: ○ | R33: ○ | S33: ○ | T33: ○ | U33: ○ | V33: ● | W33: ○ | X33: ○ | Y33: ○ | Z33: ○ | AA33: ○ | AB33: ○ | AC33: ○ | AD33: ● | AE33: ○ | AF33: ● | AG33: ○ | AH33: ○ | AI33: 2
G34: 1 | H34: ○ | I34: ○ | J34: ○ | K34: ○ | L34: ○ | M34: ● | N34: ● | O34: ○ | P34: ● | Q34: ● | R34: ○ | S34: ○ | T34: ○ | U34: ○ | V34: ○ | W34: ○ | X34: ● | Y34: ○ | Z34: ○ | AA34: ○ | AB34: ○ | AC34: ○ | AD34: ○ | AE34: ○ | AF34: ● | AG34: ● | AH34: ○ | AI34: 1
G35: 0 | H35: ○ | I35: ○ | J35: ○ | K35: ○ | L35: ○ | M35: ○ | N35: ○ | O35: ○ | P35: ○ | Q35: ○ | R35: ○ | S35: ○ | T35: ○ | U35: ○ | V35: ● | W35: ○ | X35: ○ | Y35: ○ | Z35: ○ | AA35: ○ | AB35: ○ | AC35: ○ | AD35: ● | AE35: ○ | AF35: ○ | AG35: ○ | AH35: ○ | AI35: 0
G36: 1 | H36: ○ | I36: ○ | J36: ○ | K36: ● | L36: ○ | M36: ○ | N36: ● | O36: ○ | P36: ● | Q36: ○ | R36: ○ | S36: ○ | T36: ○ | U36: ○ | V36: ○ | W36: ○ | X36: ○ | Y36: ○ | Z36: ○ | AA36: ○ | AB36: ○ | AC36: ○ | AD36: ○ | AE36: ○ | AF36: ○ | AG36: ○ | AH36: ○ | AI36: 1
G37: 2 | H37: ○ | I37: ○ | J37: ○ | K37: ○ | L37: ○ | M37: ○ | N37: ○ | O37: ○ | P37: ○ | Q37: ○ | R37: ○ | S37: ○ | T37: ○ | U37: ○ | V37: ● | W37: ○ | X37: ○ | Y37: ○ | Z37: ○ | AA37: ○ | AB37: ○ | AC37: ○ | AD37: ○ | AE37: ○ | AF37: ○ | AG37: ○ | AH37: ○ | AI37: 2
G38: 3 | H38: ○ | I38: ○ | J38: ○ | K38: ○ | L38: ○ | M38: ● | N38: ○ | O38: ○ | P38: ○ | Q38: ○ | R38: ● | S38: ● | T38: ● | U38: ○ | V38: ○ | W38: ● | X38: ● | Y38: ○ | Z38: ○ | AA38: ○ | AB38: ○ | AC38: ○ | AD38: ○ | AE38: ○ | AF38: ○ | AG38: ○ | AH38: ○ | AI38: 3
G39: 4 | H39: ○ | I39: ○ | J39: ○ | K39: ○ | L39: ○ | M39: ○ | N39: ○ | O39: ○ | P39: ○ | Q39: ○ | R39: ○ | S39: ○ | T39: ○ | U39: ○ | V39: ○ | W39: ○ | X39: ○ | Y39: ○ | Z39: ○ | AA39: ○ | AB39: ○ | AC39: ○ | AD39: ○ | AE39: ○ | AF39: ○ | AG39: ○ | AH39: ○ | AI39: 4
G40: 5 | H40: ○ | I40: ○ | J40: ○ | K40: ○ | L40: ○ | M40: ○ | N40: ○ | O40: ○ | P40: ○ | Q40: ○ | R40: ○ | S40: ○ | T40: ○ | U40: ○ | V40: ○ | W40: ○ | X40: ○ | Y40: ○ | Z40: ○ | AA40: ○ | AB40: ○ | AC40: ○ | AD40: ○ | AE40: ○ | AF40: ○ | AG40: ○ | AH40: ○ | AI40: 5 | AS40: 滑块顶棒数量 | AZ40: 35
G41: 6 | H41: ○ | I41: ○ | J41: ○ | K41: ○ | L41: ○ | M41: ○ | N41: ○ | O41: ○ | P41: ○ | Q41: ○ | R41: ○ | S41: ○ | T41: ○ | U41: ○ | V41: ○ | W41: ○ | X41: ○ | Y41: ○ | Z41: ○ | AA41: ○ | AB41: ○ | AC41: ○ | AD41: ○ | AE41: ○ | AF41: ○ | AG41: ○ | AH41: ○ | AI41: 6
H42: -13 | I42: -12 | J42: -11 | K42: -10 | L42: -9 | M42: -8 | N42: -7 | O42: -6 | P42: -5 | Q42: -4 | R42: -3 | S42: 2 | T42: 1 | U42: 0 | V42: 1 | W42: 2 | X42: 3 | Y42: 4 | Z42: 5 | AA42: 6 | AB42: 7 | AC42: 8 | AD42: 9 | AE42: 10 | AF42: 11 | AG42: 12 | AH42: 13 | AS42: 滑块气垫压力 | AZ42: 800
AS43: （± 50KN）
A44: 本工序使用的工装 | AD44: 备注
A45: 上料手 | D45: =I3 -> 11A 809 605 | O45: CBF4（左、右） | AD45: 1.巡视操作人数 1-2 人
A46: 下料手 | D46: =I3 -> 11A 809 605 | O46: CBF5（左、右） | AD46: 2.零件搬运数量：2人每次搬运1件。
A48: 本工序的操作方法
...
